Workbook
Name MinTimeChar: _xlfn.LAMBDA(_xlpm.start,_xlpm.range, _xlfn.XMATCH(TRUE, _xlfn.SCAN(0, _xlpm.range, _xlfn.LAMBDA(_xlpm.acc,_xlpm.x, _xlpm.acc + _xlpm.x >= 5/1440))))

Sheet Brussels
A5: Parameters linked to the bus
B6: Total capacity of battery | C6: E_min Minimum SOC allowed | D6: E_max Maximum SOC allowed | E6: E0 Initial SOC at start of the day | F6: Eend Min SOC allowed at end of operations' day | G6: Number of cycles that battery can last | H6: Depth of discharge of battery | I6: Battery replacement cost | J6: Number of trips per day | K6: Total energy taken from battery of bus through its lifespan
A7: Bus 501 | B7: 491 | C7: 0.25 | D7: 0.85 | E7: 0.5 | F7: 0.5 | G7: 4000 | H7: 0 | I7: =139*0.924224 -> 128.46714 | J7: 5 | K7: =G7*B7*D7 -> 1669400 | L7: =Parameter!F3 -> 123 | M7: 123
A8: Bus 502 | B8: 491 | C8: 0.25 | D8: 0.85 | E8: 0.5 | F8: 0.5 | G8: 4000 | H8: 0 | I8: =139*0.924224 -> 128.46714 | J8: 13 | K8: =G8*B8*D8 -> 1669400 | L8: =Parameter!F4 -> 353 | M8: 352
A9: Bus 503 | B9: 491 | C9: 0.25 | D9: 0.85 | E9: 0.5 | F9: 0.5 | G9: 4000 | H9: 0 | I9: =139*0.924224 -> 128.46714 | J9: 12 | K9: =G9*B9*D9 -> 1669400 | L9: =Parameter!F5 -> 405 | M9: 404
A10: Bus 504 | B10: 491 | C10: 0.25 | D10: 0.85 | E10: 0.5 | F10: 0.5 | G10: 4000 | H10: 0 | I10: =139*0.924224 -> 128.46714 | J10: 17 | K10: =G10*B10*D10 -> 1669400 | L10: =Parameter!F6 -> 401 | M10: 400
A11: Bus 505 | B11: 491 | C11: 0.25 | D11: 0.85 | E11: 0.5 | F11: 0.5 | G11: 4000 | H11: 0 | I11: =139*0.924224 -> 128.46714 | J11: 16 | K11: =G11*B11*D11 -> 1669400 | L11: =Parameter!F7 -> 404 | M11: 403
A12: Bus 506 | B12: 491 | C12: 0.25 | D12: 0.85 | E12: 0.5 | F12: 0.5 | G12: 4000 | H12: 0 | I12: =139*0.924224 -> 128.46714 | J12: 4 | K12: =G12*B12*D12 -> 1669400 | L12: =Parameter!F8 -> 108 | M12: 108
A13: Bus 507 | B13: 491 | C13: 0.25 | D13: 0.85 | E13: 0.5 | F13: 0.5 | G13: 4000 | H13: 0 | I13: =139*0.924224 -> 128.46714 | J13: 4 | K13: =G13*B13*D13 -> 1669400 | L13: =Parameter!F9 -> 113 | M13: 113
A14: Bus 508 | B14: 491 | C14: 0.25 | D14: 0.85 | E14: 0.5 | F14: 0.5 | G14: 4000 | H14: 0 | I14: =139*0.924224 -> 128.46714 | J14: 12 | K14: =G14*B14*D14 -> 1669400 | L14: =Parameter!F10 -> 336 | M14: 336
A15: Bus 509 | B15: 491 | C15: 0.25 | D15: 0.85 | E15: 0.5 | F15: 0.5 | G15: 4000 | H15: 0 | I15: =139*0.924224 -> 128.46714 | J15: 4 | K15: =G15*B15*D15 -> 1669400 | L15: =Parameter!F11 -> 118 | M15: 118
A16: Bus 510 | B16: 491 | C16: 0.25 | D16: 0.85 | E16: 0.5 | F16: 0.5 | G16: 4000 | H16: 0 | I16: =139*0.924224 -> 128.46714 | J16: 16 | K16: =G16*B16*D16 -> 1669400 | L16: =Parameter!F12 -> 400 | M16: 400
A17: Bus 511 | B17: 491 | C17: 0.25 | D17: 0.85 | E17: 0.5 | F17: 0.5 | G17: 4000 | H17: 0 | I17: =139*0.924224 -> 128.46714 | J17: 10 | K17: =G17*B17*D17 -> 1669400 | L17: =Parameter!F13 -> 295 | M17: 295
A18: Bus 512 | B18: 491 | C18: 0.25 | D18: 0.85 | E18: 0.5 | F18: 0.5 | G18: 4000 | H18: 0 | I18: =139*0.924224 -> 128.46714 | J18: 4 | K18: =G18*B18*D18 -> 1669400 | L18: =Parameter!F14 -> 127 | M18: 127
... A34: Bus 528 | B34: 491 | C34: 0.25 | D34: 0.85 | E34: 0.5 | F34: 0.5 | G34: 4000 | H34: 0 | I34: =139*0.924224 -> 128.46714 | J34: 8 | K34: =G34*B34*D34 -> 1669400 | L34: =Parameter!F30 -> 403 | M34: 403
A36: Parameters linked to the chargers
B37: Charger | C37: Charging efficiency | D37: Charging power (kW) | E37: Discharging efficiency | F37: Discharging power (kW)
A38: Overnight | B38: D0.1 | C38: 0.92 | D38: 150 | E38: 0.92 | F38: =0.8*D38 -> 120
B39: D0.2 | C39: 0.92 | D39: 150 | E39: 0.92 | F39: =0.8*D39 -> 120
B40: D0.3 | C40: 0.92 | D40: 150 | E40: 0.92 | F40: =0.8*D40 -> 120
A41: Terminal 1 | B41: D1.1 | C41: 0.92 | D41: 300 | E41: 0.92 | F41: =0.8*D41 -> 240
B42: D1.2 | C42: 0.92 | D42: 300 | E42: 0.92 | F42: =0.8*D42 -> 240
A43: Terminal 2 | B43: D2.1 | C43: 0.92 | D43: 300 | E43: 0.92 | F43: =0.8*D43 -> 240
B44: D2.2 | C44: 0.92 | D44: 300 | E44: 0.92 | F44: =0.8*D44 -> 240
A46: Parameters linked to the depots/terminals
B47: Storage capacity of ESS | C47: PV panels surface (m^2)
A48: Terminal 1 | B48: 0 | C48: 0
A49: Terminal 2 | B49: 0 | C49: 0
A50: Overnight | B50: 1228 | C50: 1876.6
B60: D0.4 | C60: 0.92 | D60: 150 | E60: 0.92 | F60: =0.8*D60 -> 120
B61: D0.5 | C61: 0.92 | D61: 150 | E61: 0.92 | F61: =0.8*D61 -> 120
B62: D0.6 | C62: 0.92 | D62: 150 | E62: 0.92 | F62: =0.8*D62 -> 120
B63: D0.7 | C63: 0.92 | D63: 150 | E63: 0.92 | F63: =0.8*D63 -> 120
B64: D0.8 | C64: 0.92 | D64: 150 | E64: 0.92 | F64: =0.8*D64 -> 120
B65: D0.9 | C65: 0.92 | D65: 150 | E65: 0.92 | F65: =0.8*D65 -> 120
B66: D0.10 | C66: 0.92 | D66: 150 | E66: 0.92 | F66: =0.8*D66 -> 120
B67: D0.11 | C67: 0.92 | D67: 150 | E67: 0.92 | F67: =0.8*D67 -> 120
B68: D0.12 | C68: 0.92 | D68: 150 | E68: 0.92 | F68: =0.8*D68 -> 120
B69: D0.13 | C69: 0.92 | D69: 150 | E69: 0.92 | F69: =0.8*D69 -> 120
B70: D0.14 | C70: 0.92 | D70: 150 | E70: 0.92 | F70: =0.8*D70 -> 120
...

Sheet Bus 53 and 46
E2: =F8*32 -> 38.779904
A3: Line 53 | J3: Line 53: WS --> HM | S3: Line 46: WS --> P | AA3: Line 46: P --> WS
A4: Distance of line (km) | B4: 14.4 | J4: Distance of line (km) | K4: 14.4 | S4: Distance length (km) | T4: =9.4+5*0.421 -> 11.505 | AA4: Distance length (km) | AB4: =9.4+5*0.421 -> 11.505
A6: Hopital Militaire (Departure) | B6: Westland Shopping (Arrival) | C6: Departure depot | D6: Time taken to travel from start to end (hrs) | E6: Avg speed (km/h) | F6: Avg consumption (kWh/km) | G6: Consumption of trip (kWh) | J6: WESTLAND SHOPPING | K6: HOP. MILITAIRE | L6: Departure Depot | M6: Time taken to travel from start to end (hrs) | N6: Avg speed (km/h) | O6: Avg consumption (kWh/km) | P6: Consumption of trip (kWh) | S6: WESTLAND SHOPPING | T6: PANNENHUIS | U6: Time taken to travel from start to end (hrs) | V6: Avg speed (km/h) | W6: Avg consumption (kWh/km) | X6: Consumption of trip (kWh) | AA6: PANNENHUIS | AB6: WESTLAND SHOPPING | AC6: Time taken to travel from start to end (hrs) | AD6: Avg speed (km/h) | AE6: Avg consumption (kWh/km) | AF6: Consumption of trip (kWh)
A7: 0.21458333 | B7: 0.24305556 | C7: D2 | D7: =24*(B7-A7) -> 0.68333333 | E7: =$K$4/D7 -> 21.073171 | F7: =0.01005*E7^2-0.3113*E7+3.484 -> 1.3869111 | G7: =F7*$K$4 -> 19.97152 | H7: 501 | J7: 0.22847222 | K7: 0.25694444 | L7: D2 | M7: =24*(K7-J7) -> 0.68333333 | N7: =$K$4/M7 -> 21.073171 | O7: =0.01005*N7^2-0.3113*N7+3.484 -> 1.3869111 | P7: =O7*$K$4 -> 19.97152 | Q7: 502 | S7: 5:17 | T7: 5:58 | U7: =(T7-S7)*24 -> 0.68333333 | V7: =$T$4/U7 -> 16.836585 | W7: =0.01005*V7^2-0.3113*V7+3.484 -> 1.0916506 | X7: =W7*$T$4 -> 12.55944 | Y7: 622 | AA7: 5:44 | AB7: 6:17 | AC7: =(AB7-AA7)*24 -> 0.55 | AD7: =$AB$4/AC7 -> 20.918182 | AE7: =0.01005*AD7^2-0.3113*AD7+3.484 -> 1.3697518 | AF7: =$AB$4*AE7 -> 15.758995 | AG7: 503
A8: 0.22083333 | B8: 0.25208333 | C8: D1 | D8: =(B8-A8)*24 -> 0.75 | E8: =$B$4/D8 -> 19.2 | F8: =0.01005*E8^2-0.3113*E8+3.484 -> 1.211872 | G8: =F8*$B$4 -> 17.450957 | H8: 504 | J8: 0.24097222 | K8: 0.26944444 | L8: D2 | M8: =24*(K8-J8) -> 0.68333333 | N8: =$K$4/M8 -> 21.073171 | O8: =0.01005*N8^2-0.3113*N8+3.484 -> 1.3869111 | P8: =O8*$K$4 -> 19.97152 | Q8: 503 | S8: 5:30 | T8: 6:11 | U8: =(T8-S8)*24 -> 0.68333333 | V8: =$T$4/U8 -> 16.836585 | W8: =0.01005*V8^2-0.3113*V8+3.484 -> 1.0916506 | X8: =W8*$T$4 -> 12.55944 | Y8: 623 | AA8: 5:57 | AB8: 6:30 | AC8: =(AB8-AA8)*24 -> 0.55 | AD8: =$AB$4/AC8 -> 20.918182 | AE8: =0.01005*AD8^2-0.3113*AD8+3.484 -> 1.3697518 | AF8: =$AB$4*AE8 -> 15.758995 | AG8: 621
A9: 0.22777778 | B9: 0.25902778 | C9: D1 | D9: =(B9-A9)*24 -> 0.75 | E9: =$B$4/D9 -> 19.2 | F9: =0.01005*E9^2-0.3113*E9+3.484 -> 1.211872 | G9: =F9*$B$4 -> 17.450957 | H9: 506 | J9: 0.25138889 | K9: 0.28055556 | L9: D2 | M9: =24*(K9-J9) -> 0.7 | N9: =$K$4/M9 -> 20.571429 | O9: =0.01005*N9^2-0.3113*N9+3.484 -> 1.3331102 | P9: =O9*$K$4 -> 19.196787 | Q9: 505 | S9: 5:42 | T9: 6:23 | U9: =(T9-S9)*24 -> 0.68333333 | V9: =$T$4/U9 -> 16.836585 | W9: =0.01005*V9^2-0.3113*V9+3.484 -> 1.0916506 | X9: =W9*$T$4 -> 12.55944 | Y9: 501 | AA9: 6:09 | AB9: 6:43 | AC9: =(AB9-AA9)*24 -> 0.56666667 | AD9: =$AB$4/AC9 -> 20.302941 | AE9: =0.01005*AD9^2-0.3113*AD9+3.484 -> 1.3063991 | AF9: =$AB$4*AE9 -> 15.030121 | AG9: 622
A10: 0.22847222 | B10: 0.25694444 | C10: D2 | D10: =24*(B10-A10) -> 0.68333333 | E10: =$K$4/D10 -> 21.073171 | F10: =0.01005*E10^2-0.3113*E10+3.484 -> 1.3869111 | G10: =F10*$K$4 -> 19.97152 | H10: 502 | J10: 0.25972222 | K10: 0.28958333 | L10: D2 | M10: =24*(K10-J10) -> 0.71666667 | N10: =$K$4/M10 -> 20.093023 | O10: =0.01005*N10^2-0.3113*N10+3.484 -> 1.2865242 | P10: =O10*$K$4 -> 18.525948 | Q10: 504 | S10: 5:54 | T10: 6:36 | U10: =(T10-S10)*24 -> 0.7 | V10: =$T$4/U10 -> 16.435714 | W10: =0.01005*V10^2-0.3113*V10+3.484 -> 1.0823958 | X10: =W10*$T$4 -> 12.452964 | Y10: 624 | AA10: 6:20 | AB10: 6:56 | AC10: =(AB10-AA10)*24 -> 0.6 | AD10: =$AB$4/AC10 -> 19.175 | AE10: =0.01005*AD10^2-0.3113*AD10+3.484 -> 1.2100128 | AF10: =$AB$4*AE10 -> 13.921197 | AG10: 505
A11: 0.23472222 | B11: 0.26597222 | C11: D1 | D11: =(B11-A11)*24 -> 0.75 | E11: =$B$4/D11 -> 19.2 | F11: =0.01005*E11^2-0.3113*E11+3.484 -> 1.211872 | G11: =F11*$B$4 -> 17.450957 | H11: 507 | J11: 0.26666667 | K11: 0.29861111 | L11: D2 | M11: =24*(K11-J11) -> 0.76666667 | N11: =$K$4/M11 -> 18.782609 | O11: =0.01005*N11^2-0.3113*N11+3.484 -> 1.1824771 | P11: =O11*$K$4 -> 17.027671 | Q11: 506 | S11: 6:06 | T11: 6:49 | U11: =(T11-S11)*24 -> 0.71666667 | V11: =$T$4/U11 -> 16.053488 | W11: =0.01005*V11^2-0.3113*V11+3.484 -> 1.0765797 | X11: =W11*$T$4 -> 12.386049 | Y11: 504 | AA11: 6:31 | AB11: 7:09 | AC11: =(AB11-AA11)*24 -> 0.63333333 | AD11: =$AB$4/AC11 -> 18.165789 | AE11: =0.01005*AD11^2-0.3113*AD11+3.484 -> 1.1454486 | AF11: =$AB$4*AE11 -> 13.178386 | AG11: 623
A12: 0.24097222 | B12: 0.27222222 | C12: D1 | D12: =(B12-A12)*24 -> 0.75 | E12: =$B$4/D12 -> 19.2 | F12: =0.01005*E12^2-0.3113*E12+3.484 -> 1.211872 | G12: =F12*$B$4 -> 17.450957 | H12: 508 | J12: 0.27361111 | K12: 0.30763889 | L12: D2 | M12: =24*(K12-J12) -> 0.81666667 | N12: =$K$4/M12 -> 17.632653 | O12: =0.01005*N12^2-0.3113*N12+3.484 -> 1.1196052 | P12: =O12*$K$4 -> 16.122314 | Q12: 507 | S12: - | T12: 6:57 | U12: =(T12-S12)*24 -> #VALUE! | V12: =$T$4/U12 -> #VALUE! | W12: =0.01005*V12^2-0.3113*V12+3.484 -> #VALUE! | X12: =W12*$T$4 -> #VALUE! | Y12: 625 | AA12: 6:39 | AB12: 7:19 | AC12: =(AB12-AA12)*24 -> 0.66666667 | AD12: =$AB$4/AC12 -> 17.2575 | AE12: =0.01005*AD12^2-0.3113*AD12+3.484 -> 1.1048444 | AF12: =$AB$4*AE12 -> 12.711235 | AG12: 501
A13: 0.24097222 | B13: 0.26944444 | C13: D2 | D13: =24*(B13-A13) -> 0.68333333 | E13: =$K$4/D13 -> 21.073171 | F13: =0.01005*E13^2-0.3113*E13+3.484 -> 1.3869111 | G13: =F13*$K$4 -> 19.97152 | H13: 503 | J13: 0.27986111 | K13: 0.31458333 | L13: D2 | M13: =24*(K13-J13) -> 0.83333333 | N13: =$K$4/M13 -> 17.28 | O13: =0.01005*N13^2-0.3113*N13+3.484 -> 1.1056499 | P13: =O13*$K$4 -> 15.921359 | Q13: 508 | S13: 6:18 | T13: 7:03 | U13: =(T13-S13)*24 -> 0.75 | V13: =$T$4/U13 -> 15.34 | W13: =0.01005*V13^2-0.3113*V13+3.484 -> 1.0735798 | X13: =W13*$T$4 -> 12.351535 | Y13: 502 | AA13: 6:47 | AB13: 7:28 | AC13: =(AB13-AA13)*24 -> 0.68333333 | AD13: =$AB$4/AC13 -> 16.836585 | AE13: =0.01005*AD13^2-0.3113*AD13+3.484 -> 1.0916506 | AF13: =$AB$4*AE13 -> 12.55944 | AG13: 508
A14: 0.24513889 | B14: 0.27638889 | C14: D1 | D14: =(B14-A14)*24 -> 0.75 | E14: =$B$4/D14 -> 19.2 | F14: =0.01005*E14^2-0.3113*E14+3.484 -> 1.211872 | G14: =F14*$B$4 -> 17.450957 | H14: 509 | J14: 0.28541667 | K14: 0.32083333 | L14: D2 | M14: =24*(K14-J14) -> 0.85 | N14: =$K$4/M14 -> 16.941176 | O14: =0.01005*N14^2-0.3113*N14+3.484 -> 1.0945965 | P14: =O14*$K$4 -> 15.76219 | Q14: 509 | S14: 6:28 | T14: 7:13 | U14: =(T14-S14)*24 -> 0.75 | V14: =$T$4/U14 -> 15.34 | W14: =0.01005*V14^2-0.3113*V14+3.484 -> 1.0735798 | X14: =W14*$T$4 -> 12.351535 | Y14: 503 | AA14: 6:54 | AB14: 7:36 | AC14: =(AB14-AA14)*24 -> 0.7 | AD14: =$AB$4/AC14 -> 16.435714 | AE14: =0.01005*AD14^2-0.3113*AD14+3.484 -> 1.0823958 | AF14: =$AB$4*AE14 -> 12.452964 | AG14: 624
A15: 0.24930556 | B15: 0.28125 | C15: D1 | D15: =(B15-A15)*24 -> 0.76666667 | E15: =$B$4/D15 -> 18.782609 | F15: =0.01005*E15^2-0.3113*E15+3.484 -> 1.1824771 | G15: =F15*$B$4 -> 17.027671 | H15: 510 | J15: 0.29027778 | K15: 0.32638889 | L15: D2 | M15: =24*(K15-J15) -> 0.86666667 | N15: =$K$4/M15 -> 16.615385 | O15: =0.01005*N15^2-0.3113*N15+3.484 -> 1.0861444 | P15: =O15*$K$4 -> 15.640479 | Q15: 510 | S15: 6:37 | T15: 7:24 | U15: =(T15-S15)*24 -> 0.78333333 | V15: =$T$4/U15 -> 14.687234 | W15: =0.01005*V15^2-0.3113*V15+3.484 -> 1.0797982 | X15: =W15*$T$4 -> 12.423079 | Y15: 506 | AA15: 7:01 | AB15: 7:44 | AC15: =(AB15-AA15)*24 -> 0.71666667 | AD15: =$AB$4/AC15 -> 16.053488 | AE15: =0.01005*AD15^2-0.3113*AD15+3.484 -> 1.0765797 | AF15: =$AB$4*AE15 -> 12.386049 | AG15: 510
A16: 0.25138889 | B16: 0.28055556 | C16: D2 | D16: =24*(B16-A16) -> 0.7 | E16: =$K$4/D16 -> 20.571429 | F16: =0.01005*E16^2-0.3113*E16+3.484 -> 1.3331102 | G16: =F16*$K$4 -> 19.196787 | H16: 505 | J16: 0.29513889 | K16: 0.33263889 | L16: D2 | M16: =24*(K16-J16) -> 0.9 | N16: =$K$4/M16 -> 16 | O16: =0.01005*N16^2-0.3113*N16+3.484 -> 1.076 | P16: =O16*$K$4 -> 15.4944 | Q16: 501 | S16: 6:44 | T16: 7:32 | U16: =(T16-S16)*24 -> 0.8 | V16: =$T$4/U16 -> 14.38125 | W16: =0.01005*V16^2-0.3113*V16+3.484 -> 1.0856614 | X16: =W16*$T$4 -> 12.490535 | Y16: 621 | AA16: 7:07 | AB16: 7:51 | AC16: =(AB16-AA16)*24 -> 0.73333333 | AD16: =$AB$4/AC16 -> 15.688636 | AE16: =0.01005*AD16^2-0.3113*AD16+3.484 -> 1.0737673 | AF16: =$AB$4*AE16 -> 12.353692 | AG16: 504
A17: 0.25347222 | B17: 0.28541667 | C17: D1 | D17: =(B17-A17)*24 -> 0.76666667 | E17: =$B$4/D17 -> 18.782609 | F17: =0.01005*E17^2-0.3113*E17+3.484 -> 1.1824771 | G17: =F17*$B$4 -> 17.027671 | H17: 501 | J17: 0.30069444 | K17: 0.33958333 | L17: D2 | M17: =24*(K17-J17) -> 0.93333333 | N17: =$K$4/M17 -> 15.428571 | O17: =0.01005*N17^2-0.3113*N17+3.484 -> 1.0733959 | P17: =O17*$K$4 -> 15.456901 | Q17: 511 | S17: 6:51 | T17: 7:40 | U17: =(T17-S17)*24 -> 0.81666667 | V17: =$T$4/U17 -> 14.087755 | W17: =0.01005*V17^2-0.3113*V17+3.484 -> 1.0930535 | X17: =W17*$T$4 -> 12.575581 | Y17: 622 | AA17: 7:14 | AB17: 7:59 | AC17: =(AB17-AA17)*24 -> 0.75 | AD17: =$AB$4/AC17 -> 15.34 | AE17: =0.01005*AD17^2-0.3113*AD17+3.484 -> 1.0735798 | AF17: =$AB$4*AE17 -> 12.351535 | AG17: 512
A18: 0.25763889 | B18: 0.29097222 | C18: D1 | D18: =(B18-A18)*24 -> 0.8 | E18: =$B$4/D18 -> 18 | F18: =0.01005*E18^2-0.3113*E18+3.484 -> 1.1368 | G18: =F18*$B$4 -> 16.36992 | H18: 511 | J18: 0.30555556 | K18: 0.34583333 | L18: D2 | M18: =24*(K18-J18) -> 0.96666667 | N18: =$K$4/M18 -> 14.896552 | O18: =0.01005*N18^2-0.3113*N18+3.484 -> 1.0768713 | P18: =O18*$K$4 -> 15.506947 | Q18: 512 | S18: 6:58 | T18: 7:48 | U18: =(T18-S18)*24 -> 0.83333333 | V18: =$T$4/U18 -> 13.806 | W18: =0.01005*V18^2-0.3113*V18+3.484 -> 1.1017788 | X18: =W18*$T$4 -> 12.675966 | Y18: 507 | AA18: 7:18 | AB18: 8:06 | AC18: =(AB18-AA18)*24 -> 0.8 | AD18: =$AB$4/AC18 -> 14.38125 | AE18: =0.01005*AD18^2-0.3113*AD18+3.484 -> 1.0856614 | AF18: =$AB$4*AE18 -> 12.490535 | AG18: 625
A19: 0.25972222 | B19: 0.28958333 | C19: D2 | D19: =24*(B19-A19) -> 0.71666667 | E19: =$K$4/D19 -> 20.093023 | F19: =0.01005*E19^2-0.3113*E19+3.484 -> 1.2865242 | G19: =F19*$K$4 -> 18.525948 | H19: 504 | J19: 0.30972222 | K19: 0.35138889 | L19: D2 | M19: =24*(K19-J19) -> 1 | N19: =$K$4/M19 -> 14.4 | O19: =0.01005*N19^2-0.3113*N19+3.484 -> 1.085248 | P19: =O19*$K$4 -> 15.627571 | Q19: 502 | S19: 7:04 | T19: 7:56 | U19: =(T19-S19)*24 -> 0.86666667 | V19: =$T$4/U19 -> 13.275 | W19: =0.01005*V19^2-0.3113*V19+3.484 -> 1.12256 | X19: =W19*$T$4 -> 12.915053 | Y19: 505 | AA19: 7:24 | AB19: 8:13 | AC19: =(AB19-AA19)*24 -> 0.81666667 | AD19: =$AB$4/AC19 -> 14.087755 | AE19: =0.01005*AD19^2-0.3113*AD19+3.484 -> 1.0930535 | AF19: =$AB$4*AE19 -> 12.575581 | AG19: 502
A20: 0.2625 | B20: 0.29583333 | C20: D1 | D20: =(B20-A20)*24 -> 0.8 | E20: =$B$4/D20 -> 18 | F20: =0.01005*E20^2-0.3113*E20+3.484 -> 1.1368 | G20: =F20*$B$4 -> 16.36992 | H20: 512 | J20: 0.31458333 | K20: 0.35694444 | L20: D2 | M20: =24*(K20-J20) -> 1.0166667 | N20: =$K$4/M20 -> 14.163934 | O20: =0.01005*N20^2-0.3113*N20+3.484 -> 1.0909684 | P20: =O20*$K$4 -> 15.709946 | Q20: 513 | S20: - | T20: 8:01 | U20: =(T20-S20)*24 -> #VALUE! | V20: =$T$4/U20 -> #VALUE! | W20: =0.01005*V20^2-0.3113*V20+3.484 -> #VALUE! | X20: =W20*$T$4 -> #VALUE! | Y20: 626 | AA20: 7:30 | AB20: 8:21 | AC20: =(AB20-AA20)*24 -> 0.85 | AD20: =$AB$4/AC20 -> 13.535294 | AE20: =0.01005*AD20^2-0.3113*AD20+3.484 -> 1.111665 | AF20: =$AB$4*AE20 -> 12.789706 | AG20: 503
A21: 0.26597222 | B21: 0.3 | C21: D1 | D21: =(B21-A21)*24 -> 0.81666667 | E21: =$B$4/D21 -> 17.632653 | F21: =0.01005*E21^2-0.3113*E21+3.484 -> 1.1196052 | G21: =F21*$B$4 -> 16.122314 | H21: 502 | J21: 0.31875 | K21: 0.36319444 | L21: D2 | M21: =24*(K21-J21) -> 1.0666667 | N21: =$K$4/M21 -> 13.5 | O21: =0.01005*N21^2-0.3113*N21+3.484 -> 1.1130625 | P21: =O21*$K$4 -> 16.0281 | Q21: 514 | S21: 7:12 | T21: 8:05 | U21: =(T21-S21)*24 -> 0.88333333 | V21: =$T$4/U21 -> 13.024528 | W21: =0.01005*V21^2-0.3113*V21+3.484 -> 1.1343296 | X21: =W21*$T$4 -> 13.050462 | Y21: 509 | AA21: 7:37 | AB21: 8:28 | AC21: =(AB21-AA21)*24 -> 0.85 | AD21: =$AB$4/AC21 -> 13.535294 | AE21: =0.01005*AD21^2-0.3113*AD21+3.484 -> 1.111665 | AF21: =$AB$4*AE21 -> 12.789706 | AG21: 513
A22: 0.26666667 | B22: 0.29861111 | C22: D2 | D22: =24*(B22-A22) -> 0.76666667 | E22: =$K$4/D22 -> 18.782609 | F22: =0.01005*E22^2-0.3113*E22+3.484 -> 1.1824771 | G22: =F22*$K$4 -> 17.027671 | H22: 506 | J22: 0.32430556 | K22: 0.36805556 | L22: D2 | M22: =24*(K22-J22) -> 1.05 | N22: =$K$4/M22 -> 13.714286 | O22: =0.01005*N22^2-0.3113*N22+3.484 -> 1.1049633 | P22: =O22*$K$4 -> 15.911471 | Q22: 515 | S22: 7:19 | T22: 8:14 | U22: =(T22-S22)*24 -> 0.91666667 | V22: =$T$4/U22 -> 12.550909 | W22: =0.01005*V22^2-0.3113*V22+3.484 -> 1.1600315 | X22: =W22*$T$4 -> 13.346162 | Y22: 623 | AA22: 7:44 | AB22: 8:36 | AC22: =(AB22-AA22)*24 -> 0.86666667 | AD22: =$AB$4/AC22 -> 13.275 | AE22: =0.01005*AD22^2-0.3113*AD22+3.484 -> 1.12256 | AF22: =$AB$4*AE22 -> 12.915053 | AG22: 506
A23: 0.27083333 | B23: 0.30486111 | C23: D1 | D23: =(B23-A23)*24 -> 0.81666667 | E23: =$B$4/D23 -> 17.632653 | F23: =0.01005*E23^2-0.3113*E23+3.484 -> 1.1196052 | G23: =F23*$B$4 -> 16.122314 | H23: 513 | J23: 0.32986111 | K23: 0.37291667 | L23: D2 | M23: =24*(K23-J23) -> 1.0333333 | N23: =$K$4/M23 -> 13.935484 | O23: =0.01005*N23^2-0.3113*N23+3.484 -> 1.0975709 | P23: =O23*$K$4 -> 15.80502 | Q23: 503 | S23: 7:27 | T23: 8:23 | U23: =(T23-S23)*24 -> 0.93333333 | V23: =$T$4/U23 -> 12.326786 | W23: =0.01005*V23^2-0.3113*V23+3.484 -> 1.1737655 | X23: =W23*$T$4 -> 13.504173 | Y23: 511 | AA23: 7:51 | AB23: 8:43 | AC23: =(AB23-AA23)*24 -> 0.86666667 | AD23: =$AB$4/AC23 -> 13.275 | AE23: =0.01005*AD23^2-0.3113*AD23+3.484 -> 1.12256 | AF23: =$AB$4*AE23 -> 12.915053 | AG23: 621
A24: 0.27361111 | B24: 0.30763889 | C24: D2 | D24: =24*(B24-A24) -> 0.81666667 | E24: =$K$4/D24 -> 17.632653 | F24: =0.01005*E24^2-0.3113*E24+3.484 -> 1.1196052 | G24: =F24*$K$4 -> 16.122314 | H24: 507 | J24: 0.33402778 | K24: 0.37847222 | L24: D2 | M24: =24*(K24-J24) -> 1.0666667 | N24: =$K$4/M24 -> 13.5 | O24: =0.01005*N24^2-0.3113*N24+3.484 -> 1.1130625 | P24: =O24*$K$4 -> 16.0281 | Q24: 516 | S24: 7:33 | T24: 8:30 | U24: =(T24-S24)*24 -> 0.95 | V24: =$T$4/U24 -> 12.110526 | W24: =0.01005*V24^2-0.3113*V24+3.484 -> 1.1879749 | X24: =W24*$T$4 -> 13.667651 | Y24: 501 | AA24: 7:59 | AB24: 8:51 | AC24: =(AB24-AA24)*24 -> 0.86666667 | AD24: =$AB$4/AC24 -> 13.275 | AE24: =0.01005*AD24^2-0.3113*AD24+3.484 -> 1.12256 | AF24: =$AB$4*AE24 -> 12.915053 | AG24: 622
A25: 0.27430556 | B25: 0.30902778 | C25: D1 | D25: =(B25-A25)*24 -> 0.83333333 | E25: =$B$4/D25 -> 17.28 | F25: =0.01005*E25^2-0.3113*E25+3.484 -> 1.1056499 | G25: =F25*$B$4 -> 15.921359 | H25: 514 | J25: 0.33958333 | K25: 0.38402778 | L25: D2 | M25: =24*(K25-J25) -> 1.0666667 | N25: =$K$4/M25 -> 13.5 | O25: =0.01005*N25^2-0.3113*N25+3.484 -> 1.1130625 | P25: =O25*$K$4 -> 16.0281 | Q25: 505 | S25: 7:41 | T25: 8:39 | U25: =(T25-S25)*24 -> 0.96666667 | V25: =$T$4/U25 -> 11.901724 | W25: =0.01005*V25^2-0.3113*V25+3.484 -> 1.2025862 | X25: =W25*$T$4 -> 13.835754 | Y25: 508 | AA25: 8:05 | AB25: 8:58 | AC25: =(AB25-AA25)*24 -> 0.88333333 | AD25: =$AB$4/AC25 -> 13.024528 | AE25: =0.01005*AD25^2-0.3113*AD25+3.484 -> 1.1343296 | AF25: =$AB$4*AE25 -> 13.050462 | AG25: 507
A26: 0.27847222 | B26: 0.31458333 | C26: D1 | D26: =(B26-A26)*24 -> 0.86666667 | E26: =$B$4/D26 -> 16.615385 | F26: =0.01005*E26^2-0.3113*E26+3.484 -> 1.0861444 | G26: =F26*$B$4 -> 15.640479 | H26: 515 | J26: 0.34513889 | K26: 0.38888889 | L26: D2 | M26: =24*(K26-J26) -> 1.05 | N26: =$K$4/M26 -> 13.714286 | O26: =0.01005*N26^2-0.3113*N26+3.484 -> 1.1049633 | P26: =O26*$K$4 -> 15.911471 | Q26: 517 | S26: 7:49 | T26: 8:48 | U26: =(T26-S26)*24 -> 0.98333333 | V26: =$T$4/U26 -> 11.7 | W26: =0.01005*V26^2-0.3113*V26+3.484 -> 1.2175345 | X26: =W26*$T$4 -> 14.007734 | Y26: 624 | AA26: 8:13 | AB26: 9:06 | AC26: =(AB26-AA26)*24 -> 0.88333333 | AD26: =$AB$4/AC26 -> 13.024528 | AE26: =0.01005*AD26^2-0.3113*AD26+3.484 -> 1.1343296 | AF26: =$AB$4*AE26 -> 13.050462 | AG26: 505
A27: 0.27986111 | B27: 0.31458333 | C27: D2 | D27: =24*(B27-A27) -> 0.83333333 | E27: =$K$4/D27 -> 17.28 | F27: =0.01005*E27^2-0.3113*E27+3.484 -> 1.1056499 | G27: =F27*$K$4 -> 15.921359 | H27: 508 | J27: 0.35138889 | K27: 0.39444444 | L27: D2 | M27: =24*(K27-J27) -> 1.0333333 | N27: =$K$4/M27 -> 13.935484 | O27: =0.01005*N27^2-0.3113*N27+3.484 -> 1.0975709 | P27: =O27*$K$4 -> 15.80502 | Q27: 518 | S27: 7:57 | T27: 8:56 | U27: =(T27-S27)*24 -> 0.98333333 | V27: =$T$4/U27 -> 11.7 | W27: =0.01005*V27^2-0.3113*V27+3.484 -> 1.2175345 | X27: =W27*$T$4 -> 14.007734 | Y27: 510 | AA27: 8:20 | AB27: 9:13 | AC27: =(AB27-AA27)*24 -> 0.88333333 | AD27: =$AB$4/AC27 -> 13.024528 | AE27: =0.01005*AD27^2-0.3113*AD27+3.484 -> 1.1343296 | AF27: =$AB$4*AE27 -> 13.050462 | AG27: 626
A28: 0.28194444 | B28: 0.31875 | C28: D1 | D28: =(B28-A28)*24 -> 0.88333333 | E28: =$B$4/D28 -> 16.301887 | F28: =0.01005*E28^2-0.3113*E28+3.484 -> 1.0800253 | G28: =F28*$B$4 -> 15.552365 | H28: 503 | J28: 0.35833333 | K28: 0.4 | L28: D2 | M28: =24*(K28-J28) -> 1 | N28: =$K$4/M28 -> 14.4 | O28: =0.01005*N28^2-0.3113*N28+3.484 -> 1.085248 | P28: =O28*$K$4 -> 15.627571 | Q28: 504 | S28: 8:03 | T28: 9:03 | U28: =(T28-S28)*24 -> 1 | V28: =$T$4/U28 -> 11.505 | W28: =0.01005*V28^2-0.3113*V28+3.484 -> 1.232762 | X28: =W28*$T$4 -> 14.182927 | Y28: 504 | AA28: 8:28 | AB28: 9:21 | AC28: =(AB28-AA28)*24 -> 0.88333333 | AD28: =$AB$4/AC28 -> 13.024528 | AE28: =0.01005*AD28^2-0.3113*AD28+3.484 -> 1.1343296 | AF28: =$AB$4*AE28 -> 13.050462 | AG28: 509
A29: 0.28541667 | B29: 0.32083333 | C29: D2 | D29: =24*(B29-A29) -> 0.85 | E29: =$K$4/D29 -> 16.941176 | F29: =0.01005*E29^2-0.3113*E29+3.484 -> 1.0945965 | G29: =F29*$K$4 -> 15.76219 | H29: 509 | J29: 0.36458333 | K29: 0.40416667 | L29: D2 | M29: =24*(K29-J29) -> 0.95 | N29: =$K$4/M29 -> 15.157895 | O29: =0.01005*N29^2-0.3113*N29+3.484 -> 1.0744532 | P29: =O29*$K$4 -> 15.472126 | Q29: 506 | S29: 8:11 | T29: 9:11 | U29: =(T29-S29)*24 -> 1 | V29: =$T$4/U29 -> 11.505 | W29: =0.01005*V29^2-0.3113*V29+3.484 -> 1.232762 | X29: =W29*$T$4 -> 14.182927 | Y29: 512 | AA29: 8:36 | AB29: 9:27 | AC29: =(AB29-AA29)*24 -> 0.85 | AD29: =$AB$4/AC29 -> 13.535294 | AE29: =0.01005*AD29^2-0.3113*AD29+3.484 -> 1.111665 | AF29: =$AB$4*AE29 -> 12.789706 | AG29: 623
A30: 0.28680556 | B30: 0.32361111 | C30: D1 | D30: =(B30-A30)*24 -> 0.88333333 | E30: =$B$4/D30 -> 16.301887 | F30: =0.01005*E30^2-0.3113*E30+3.484 -> 1.0800253 | G30: =F30*$B$4 -> 15.552365 | H30: 516 | J30: 0.37083333 | K30: 0.40902778 | L30: D2 | M30: =24*(K30-J30) -> 0.91666667 | N30: =$K$4/M30 -> 15.709091 | O30: =0.01005*N30^2-0.3113*N30+3.484 -> 1.0738541 | P30: =O30*$K$4 -> 15.4635 | Q30: 519 | S30: 8:18 | T30: 9:18 | U30: =(T30-S30)*24 -> 1 | V30: =$T$4/U30 -> 11.505 | W30: =0.01005*V30^2-0.3113*V30+3.484 -> 1.232762 | X30: =W30*$T$4 -> 14.182927 | Y30: 625 | AA30: 8:44 | AB30: 9:35 | AC30: =(AB30-AA30)*24 -> 0.85 | AD30: =$AB$4/AC30 -> 13.535294 | AE30: =0.01005*AD30^2-0.3113*AD30+3.484 -> 1.111665 | AF30: =$AB$4*AE30 -> 12.789706 | AG30: 511
A31: 0.29027778 | B31: 0.32638889 | C31: D2 | D31: =24*(B31-A31) -> 0.86666667 | E31: =$K$4/D31 -> 16.615385 | F31: =0.01005*E31^2-0.3113*E31+3.484 -> 1.0861444 | G31: =F31*$K$4 -> 15.640479 | H31: 510 | J31: 0.37708333 | K31: 0.41388889 | L31: D2 | M31: =24*(K31-J31) -> 0.88333333 | N31: =$K$4/M31 -> 16.301887 | O31: =0.01005*N31^2-0.3113*N31+3.484 -> 1.0800253 | P31: =O31*$K$4 -> 15.552365 | Q31: 507 | S31: 8:26 | T31: 9:26 | U31: =(T31-S31)*24 -> 1 | V31: =$T$4/U31 -> 11.505 | W31: =0.01005*V31^2-0.3113*V31+3.484 -> 1.232762 | X31: =W31*$T$4 -> 14.182927 | Y31: 502 | AA31: 8:51 | AB31: 9:42 | AC31: =(AB31-AA31)*24 -> 0.85 | AD31: =$AB$4/AC31 -> 13.535294 | AE31: =0.01005*AD31^2-0.3113*AD31+3.484 -> 1.111665 | AF31: =$AB$4*AE31 -> 12.789706 | AG31: 501
A32: 0.29166667 | B32: 0.32986111 | C32: D1 | D32: =(B32-A32)*24 -> 0.91666667 | E32: =$B$4/D32 -> 15.709091 | F32: =0.01005*E32^2-0.3113*E32+3.484 -> 1.0738541 | G32: =F32*$B$4 -> 15.4635 | H32: 505 | J32: 0.38194444 | K32: 0.41875 | L32: D2 | M32: =24*(K32-J32) -> 0.88333333 | N32: =$K$4/M32 -> 16.301887 | O32: =0.01005*N32^2-0.3113*N32+3.484 -> 1.0800253 | P32: =O32*$K$4 -> 15.552365 | Q32: 508 | S32: 8:33 | T32: 9:33 | U32: =(T32-S32)*24 -> 1 | V32: =$T$4/U32 -> 11.505 | W32: =0.01005*V32^2-0.3113*V32+3.484 -> 1.232762 | X32: =W32*$T$4 -> 14.182927 | Y32: 503 | AA32: 8:59 | AB32: 9:50 | AC32: =(AB32-AA32)*24 -> 0.85 | AD32: =$AB$4/AC32 -> 13.535294 | AE32: =0.01005*AD32^2-0.3113*AD32+3.484 -> 1.111665 | AF32: =$AB$4*AE32 -> 12.789706 | AG32: 508
A33: 0.29513889 | B33: 0.33263889 | C33: D2 | D33: =24*(B33-A33) -> 0.9 | E33: =$K$4/D33 -> 16 | F33: =0.01005*E33^2-0.3113*E33+3.484 -> 1.076 | G33: =F33*$K$4 -> 15.4944 | H33: 501 | J33: 0.38680556 | K33: 0.42291667 | L33: D2 | M33: =24*(K33-J33) -> 0.86666667 | N33: =$K$4/M33 -> 16.615385 | O33: =0.01005*N33^2-0.3113*N33+3.484 -> 1.0861444 | P33: =O33*$K$4 -> 15.640479 | Q33: 520 | S33: 8:40 | T33: 9:39 | U33: =(T33-S33)*24 -> 0.98333333 | V33: =$T$4/U33 -> 11.7 | W33: =0.01005*V33^2-0.3113*V33+3.484 -> 1.2175345 | X33: =W33*$T$4 -> 14.007734 | Y33: 513 | AA33: 9:05 | AB33: 9:57 | AC33: =(AB33-AA33)*24 -> 0.86666667 | AD33: =$AB$4/AC33 -> 13.275 | AE33: =0.01005*AD33^2-0.3113*AD33+3.484 -> 1.12256 | AF33: =$AB$4*AE33 -> 12.915053 | AG33: 624
A34: 0.29652778 | B34: 0.33541667 | C34: D1 | D34: =(B34-A34)*24 -> 0.93333333 | E34: =$B$4/D34 -> 15.428571 | F34: =0.01005*E34^2-0.3113*E34+3.484 -> 1.0733959 | G34: =F34*$B$4 -> 15.456901 | H34: 517 | J34: 0.39236111 | K34: 0.42777778 | L34: D2 | M34: =24*(K34-J34) -> 0.85 | N34: =$K$4/M34 -> 16.941176 | O34: =0.01005*N34^2-0.3113*N34+3.484 -> 1.0945965 | P34: =O34*$K$4 -> 15.76219 | Q34: 509 | S34: 8:47 | T34: 9:45 | U34: =(T34-S34)*24 -> 0.96666667 | V34: =$T$4/U34 -> 11.901724 | W34: =0.01005*V34^2-0.3113*V34+3.484 -> 1.2025862 | X34: =W34*$T$4 -> 13.835754 | Y34: 506 | AA34: 9:13 | AB34: 10:05 | AC34: =(AB34-AA34)*24 -> 0.86666667 | AD34: =$AB$4/AC34 -> 13.275 | AE34: =0.01005*AD34^2-0.3113*AD34+3.484 -> 1.12256 | AF34: =$AB$4*AE34 -> 12.915053 | AG34: 510
A35: 0.30069444 | B35: 0.34166667 | C35: D1 | D35: =(B35-A35)*24 -> 0.98333333 | E35: =$B$4/D35 -> 14.644068 | F35: =0.01005*E35^2-0.3113*E35+3.484 -> 1.0805113 | G35: =F35*$B$4 -> 15.559363 | H35: 518 | J35: 0.39722222 | K35: 0.43194444 | L35: D2 | M35: =24*(K35-J35) -> 0.83333333 | N35: =$K$4/M35 -> 17.28 | O35: =0.01005*N35^2-0.3113*N35+3.484 -> 1.1056499 | P35: =O35*$K$4 -> 15.921359 | Q35: 510 | S35: 8:54 | T35: 9:51 | U35: =(T35-S35)*24 -> 0.95 | V35: =$T$4/U35 -> 12.110526 | W35: =0.01005*V35^2-0.3113*V35+3.484 -> 1.1879749 | X35: =W35*$T$4 -> 13.667651 | Y35: 621 | AA35: 9:21 | AB35: 10:13 | AC35: =(AB35-AA35)*24 -> 0.86666667 | AD35: =$AB$4/AC35 -> 13.275 | AE35: =0.01005*AD35^2-0.3113*AD35+3.484 -> 1.12256 | AF35: =$AB$4*AE35 -> 12.915053 | AG35: 504
A36: 0.30069444 | B36: 0.33958333 | C36: D2 | D36: =24*(B36-A36) -> 0.93333333 | E36: =$K$4/D36 -> 15.428571 | F36: =0.01005*E36^2-0.3113*E36+3.484 -> 1.0733959 | G36: =F36*$K$4 -> 15.456901 | H36: 511 | J36: 0.40208333 | K36: 0.43680556 | L36: D2 | M36: =24*(K36-J36) -> 0.83333333 | N36: =$K$4/M36 -> 17.28 | O36: =0.01005*N36^2-0.3113*N36+3.484 -> 1.1056499 | P36: =O36*$K$4 -> 15.921359 | Q36: 501 | S36: 9:02 | T36: 9:58 | U36: =(T36-S36)*24 -> 0.93333333 | V36: =$T$4/U36 -> 12.326786 | W36: =0.01005*V36^2-0.3113*V36+3.484 -> 1.1737655 | X36: =W36*$T$4 -> 13.504173 | Y36: 622 | AA36: 9:28 | AB36: 10:20 | AC36: =(AB36-AA36)*24 -> 0.86666667 | AD36: =$AB$4/AC36 -> 13.275 | AE36: =0.01005*AD36^2-0.3113*AD36+3.484 -> 1.12256 | AF36: =$AB$4*AE36 -> 12.915053 | AG36: 512
A37: 0.30555556 | B37: 0.34583333 | C37: D2 | D37: =24*(B37-A37) -> 0.96666667 | E37: =$K$4/D37 -> 14.896552 | F37: =0.01005*E37^2-0.3113*E37+3.484 -> 1.0768713 | G37: =F37*$K$4 -> 15.506947 | H37: 512 | J37: 0.40694444 | K37: 0.44166667 | L37: D2 | M37: =24*(K37-J37) -> 0.83333333 | N37: =$K$4/M37 -> 17.28 | O37: =0.01005*N37^2-0.3113*N37+3.484 -> 1.1056499 | P37: =O37*$K$4 -> 15.921359 | Q37: 511 | S37: 9:10 | T37: 10:06 | U37: =(T37-S37)*24 -> 0.93333333 | V37: =$T$4/U37 -> 12.326786 | W37: =0.01005*V37^2-0.3113*V37+3.484 -> 1.1737655 | X37: =W37*$T$4 -> 13.504173 | Y37: 507 | AA37: 9:35 | AB37: 10:28 | AC37: =(AB37-AA37)*24 -> 0.88333333 | AD37: =$AB$4/AC37 -> 13.024528 | AE37: =0.01005*AD37^2-0.3113*AD37+3.484 -> 1.1343296 | AF37: =$AB$4*AE37 -> 13.050462 | AG37: 625
A38: 0.30625 | B38: 0.34861111 | C38: D1 | D38: =(B38-A38)*24 -> 1.0166667 | E38: =$B$4/D38 -> 14.163934 | F38: =0.01005*E38^2-0.3113*E38+3.484 -> 1.0909684 | G38: =F38*$B$4 -> 15.709946 | H38: 504 | J38: 0.41180556 | K38: 0.44652778 | L38: D2 | M38: =24*(K38-J38) -> 0.83333333 | N38: =$K$4/M38 -> 17.28 | O38: =0.01005*N38^2-0.3113*N38+3.484 -> 1.1056499 | P38: =O38*$K$4 -> 15.921359 | Q38: 512 | S38: 9:18 | T38: 10:13 | U38: =(T38-S38)*24 -> 0.91666667 | V38: =$T$4/U38 -> 12.550909 | W38: =0.01005*V38^2-0.3113*V38+3.484 -> 1.1600315 | X38: =W38*$T$4 -> 13.346162 | Y38: 505 | AA38: 9:42 | AB38: 10:35 | AC38: =(AB38-AA38)*24 -> 0.88333333 | AD38: =$AB$4/AC38 -> 13.024528 | AE38: =0.01005*AD38^2-0.3113*AD38+3.484 -> 1.1343296 | AF38: =$AB$4*AE38 -> 13.050462 | AG38: 502
A39: 0.30972222 | B39: 0.35138889 | C39: D2 | D39: =24*(B39-A39) -> 1 | E39: =$K$4/D39 -> 14.4 | F39: =0.01005*E39^2-0.3113*E39+3.484 -> 1.085248 | G39: =F39*$K$4 -> 15.627571 | H39: 502 | J39: 0.41666667 | K39: 0.45138889 | L39: D2 | M39: =24*(K39-J39) -> 0.83333333 | N39: =$K$4/M39 -> 17.28 | O39: =0.01005*N39^2-0.3113*N39+3.484 -> 1.1056499 | P39: =O39*$K$4 -> 15.921359 | Q39: 502 | S39: 9:25 | T39: 10:18 | U39: =(T39-S39)*24 -> 0.88333333 | V39: =$T$4/U39 -> 13.024528 | W39: =0.01005*V39^2-0.3113*V39+3.484 -> 1.1343296 | X39: =W39*$T$4 -> 13.050462 | Y39: 626 | AA39: 9:50 | AB39: 10:43 | AC39: =(AB39-AA39)*24 -> 0.88333333 | AD39: =$AB$4/AC39 -> 13.024528 | AE39: =0.01005*AD39^2-0.3113*AD39+3.484 -> 1.1343296 | AF39: =$AB$4*AE39 -> 13.050462 | AG39: 503
A40: 0.31111111 | B40: 0.35416667 | C40: D1 | D40: =(B40-A40)*24 -> 1.0333333 | E40: =$B$4/D40 -> 13.935484 | F40: =0.01005*E40^2-0.3113*E40+3.484 -> 1.0975709 | G40: =F40*$B$4 -> 15.80502 | H40: 506 | J40: 0.42222222 | K40: 0.45694444 | L40: D2 | M40: =24*(K40-J40) -> 0.83333333 | N40: =$K$4/M40 -> 17.28 | O40: =0.01005*N40^2-0.3113*N40+3.484 -> 1.1056499 | P40: =O40*$K$4 -> 15.921359 | Q40: 514 | S40: 9:33 | T40: 10:26 | U40: =(T40-S40)*24 -> 0.88333333 | V40: =$T$4/U40 -> 13.024528 | W40: =0.01005*V40^2-0.3113*V40+3.484 -> 1.1343296 | X40: =W40*$T$4 -> 13.050462 | Y40: 509 | AA40: 9:58 | AB40: 10:50 | AC40: =(AB40-AA40)*24 -> 0.86666667 | AD40: =$AB$4/AC40 -> 13.275 | AE40: =0.01005*AD40^2-0.3113*AD40+3.484 -> 1.12256 | AF40: =$AB$4*AE40 -> 12.915053 | AG40: 513
A41: 0.31458333 | B41: 0.35694444 | C41: D2 | D41: =24*(B41-A41) -> 1.0166667 | E41: =$K$4/D41 -> 14.163934 | F41: =0.01005*E41^2-0.3113*E41+3.484 -> 1.0909684 | G41: =F41*$K$4 -> 15.709946 | H41: 513 | J41: 0.42986111 | K41: 0.46458333 | L41: D2 | M41: =24*(K41-J41) -> 0.83333333 | N41: =$K$4/M41 -> 17.28 | O41: =0.01005*N41^2-0.3113*N41+3.484 -> 1.1056499 | P41: =O41*$K$4 -> 15.921359 | Q41: 515 | S41: 9:40 | T41: 10:34 | U41: =(T41-S41)*24 -> 0.9 | V41: =$T$4/U41 -> 12.783333 | W41: =0.01005*V41^2-0.3113*V41+3.484 -> 1.1468551 | X41: =W41*$T$4 -> 13.194568 | Y41: 623 | AA41: 10:06 | AB41: 10:58 | AC41: =(AB41-AA41)*24 -> 0.86666667 | AD41: =$AB$4/AC41 -> 13.275 | AE41: =0.01005*AD41^2-0.3113*AD41+3.484 -> 1.12256 | AF41: =$AB$4*AE41 -> 12.915053 | AG41: 621
A42: 0.31597222 | B42: 0.36041667 | C42: D1 | D42: =(B42-A42)*24 -> 1.0666667 | E42: =$B$4/D42 -> 13.5 | F42: =0.01005*E42^2-0.3113*E42+3.484 -> 1.1130625 | G42: =F42*$B$4 -> 16.0281 | H42: 519 | J42: 0.43819444 | K42: 0.47291667 | L42: D2 | M42: =24*(K42-J42) -> 0.83333333 | N42: =$K$4/M42 -> 17.28 | O42: =0.01005*N42^2-0.3113*N42+3.484 -> 1.1056499 | P42: =O42*$K$4 -> 15.921359 | Q42: 503 | S42: 9:48 | T42: 10:42 | U42: =(T42-S42)*24 -> 0.9 | V42: =$T$4/U42 -> 12.783333 | W42: =0.01005*V42^2-0.3113*V42+3.484 -> 1.1468551 | X42: =W42*$T$4 -> 13.194568 | Y42: 511 | AA42: 10:13 | AB42: 11:05 | AC42: =(AB42-AA42)*24 -> 0.86666667 | AD42: =$AB$4/AC42 -> 13.275 | AE42: =0.01005*AD42^2-0.3113*AD42+3.484 -> 1.12256 | AF42: =$AB$4*AE42 -> 12.915053 | AG42: 622
...

Sheet Trips
A1: Trip index | B1: Departure time | C1: Arrival Time | D1: Bus assigned | E1: Departure Depot | F1: Arrival Depot | G1: Distance of trip | H1: Consumption of Trip (kWh/km) | I1: Events covered | J1: Arrival/Departure at D0 | K1: Arrival D0 | L1: Arrival/Departure at D1 | M1: Arrival/Departure at D2 | N1: Duration of trip (hrs) | O1: Avg Speed during trip (km/h) | P1: Avg Speed during trip (m/s) | Q1: Consumption of trip (kWh)
A2: 1 | B2: 0.19861111 | C2: 0.24305556 | D2: 501 | E2: =IF(COUNTIF($D$2:D2,D2)=1,"D0",'Bus 53 and 46'!C7) -> D0 | F2: =IF(COUNTIF(D2:$D$233,D2)=1, "D0", IF('Bus 53 and 46'!C7 = "D2", "D1","D2")) -> D1 | G2: 32 | H2: =0.01005*(P2)^2-0.3113*P2+3.484 -> 1.58775 | I2: {=_xlfn.TEXTJOIN(", ", TRUE, _xlfn._xlws.FILTER('Events only'!$C$2:$C$411, ((Trips!B2 <= 'Events only'!$A$2:$A$411) * (Trips!C2 > 'Events only'!$A$2:$A$411)) + ((Trips!B2 > Trips!C2) * ((Trips!B2 <= 'Events only'!$A$2:$A$411) + ('Events only'!$A$2:$A$411 < Trips!C2))), "No Match"))} -> 1, 2, 3, 4, 5, 6, 7, 8, 9, 10, 11 | J2: =IF(E2="D0",LEFT(I2,FIND(",",I2)-1),IF(F2="D0",RIGHT(I2,LEN(I2)-FIND("#",SUBSTITUTE(I2,",","#",LEN(I2)-LEN(SUBSTITUTE(I2,",",""))))),"- ")) -> 1 | K2: =IF(F2="D0",RIGHT(I2,LEN(I2)-FIND("#",SUBSTITUTE(I2,",","#",LEN(I2)-LEN(SUBSTITUTE(I2,",",""))))),"- ") -> - | L2: =IF(E2="D1",LEFT(I2,FIND(",",I2)-1),IF(F2="D1",RIGHT(I2,LEN(I2)-FIND("#",SUBSTITUTE(I2,",","#",LEN(I2)-LEN(SUBSTITUTE(I2,",","")))))," - ")) -> 11 | M2: =IF(E2="D2",LEFT(I2,FIND(",",I2)-1),IF(F2="D2",RIGHT(I2,LEN(I2)-FIND("#",SUBSTITUTE(I2,",","#",LEN(I2)-LEN(SUBSTITUTE(I2,",","")))))," - ")) -> - | N2: =24*(C2-B2) -> 1.0666667 | O2: =G2/N2 -> 30 | P2: =O2*(10/36) -> 8.3333333 | Q2: 44.381156
A3: 2 | B3: 0.21388889 | C3: 0.25208333 | D3: 504 | E3: =IF(COUNTIF($D$2:D3,D3)=1,"D0",'Bus 53 and 46'!C8) -> D0 | F3: =IF(COUNTIF(D3:$D$233,D3)=1, "D0", IF('Bus 53 and 46'!C8 = "D2", "D1","D2")) -> D2 | G3: 16.8 | H3: =0.01005*(P3)^2-0.3113*P3+3.484 -> 2.1596694 | I3: {=_xlfn.TEXTJOIN(", ", TRUE, _xlfn._xlws.FILTER('Events only'!$C$2:$C$411, ((Trips!B3 <= 'Events only'!$A$2:$A$411) * (Trips!C3 > 'Events only'!$A$2:$A$411)) + ((Trips!B3 > Trips!C3) * ((Trips!B3 <= 'Events only'!$A$2:$A$411) + ('Events only'!$A$2:$A$411 < Trips!C3))), "No Match"))} -> 4, 5, 6, 7, 8, 9, 10, 11, 12, 13, 14 | J3: =IF(E3="D0",LEFT(I3,FIND(",",I3)-1),IF(F3="D0",RIGHT(I3,LEN(I3)-FIND("#",SUBSTITUTE(I3,",","#",LEN(I3)-LEN(SUBSTITUTE(I3,",",""))))),"- ")) -> 4 | K3: =IF(F3="D0",RIGHT(I3,LEN(I3)-FIND("#",SUBSTITUTE(I3,",","#",LEN(I3)-LEN(SUBSTITUTE(I3,",",""))))),"- ") -> - | L3: =IF(E3="D1",LEFT(I3,FIND(",",I3)-1),IF(F3="D1",RIGHT(I3,LEN(I3)-FIND("#",SUBSTITUTE(I3,",","#",LEN(I3)-LEN(SUBSTITUTE(I3,",","")))))," - ")) -> - | M3: =IF(E3="D2",LEFT(I3,FIND(",",I3)-1),IF(F3="D2",RIGHT(I3,LEN(I3)-FIND("#",SUBSTITUTE(I3,",","#",LEN(I3)-LEN(SUBSTITUTE(I3,",","")))))," - ")) -> 14 | N3: =24*(C3-B3) -> 0.91666667 | O3: =G3/N3 -> 18.327273 | P3: =O3*(10/36) -> 5.0909091 | Q3: 20.35945
A4: 3 | B4: 0.22083333 | C4: 0.25902778 | D4: 506 | E4: =IF(COUNTIF($D$2:D4,D4)=1,"D0",'Bus 53 and 46'!C9) -> D0 | F4: =IF(COUNTIF(D4:$D$233,D4)=1, "D0", IF('Bus 53 and 46'!C9 = "D2", "D1","D2")) -> D2 | G4: 16.8 | H4: =0.01005*(P4)^2-0.3113*P4+3.484 -> 2.1596694 | I4: {=_xlfn.TEXTJOIN(", ", TRUE, _xlfn._xlws.FILTER('Events only'!$C$2:$C$411, ((Trips!B4 <= 'Events only'!$A$2:$A$411) * (Trips!C4 > 'Events only'!$A$2:$A$411)) + ((Trips!B4 > Trips!C4) * ((Trips!B4 <= 'Events only'!$A$2:$A$411) + ('Events only'!$A$2:$A$411 < Trips!C4))), "No Match"))} -> 5, 6, 7, 8, 9, 10, 11, 12, 13, 14, 15, 16, 17, 18 | J4: =IF(E4="D0",LEFT(I4,FIND(",",I4)-1),IF(F4="D0",RIGHT(I4,LEN(I4)-FIND("#",SUBSTITUTE(I4,",","#",LEN(I4)-LEN(SUBSTITUTE(I4,",",""))))),"- ")) -> 5 | K4: =IF(F4="D0",RIGHT(I4,LEN(I4)-FIND("#",SUBSTITUTE(I4,",","#",LEN(I4)-LEN(SUBSTITUTE(I4,",",""))))),"- ") -> - | L4: =IF(E4="D1",LEFT(I4,FIND(",",I4)-1),IF(F4="D1",RIGHT(I4,LEN(I4)-FIND("#",SUBSTITUTE(I4,",","#",LEN(I4)-LEN(SUBSTITUTE(I4,",","")))))," - ")) -> - | M4: =IF(E4="D2",LEFT(I4,FIND(",",I4)-1),IF(F4="D2",RIGHT(I4,LEN(I4)-FIND("#",SUBSTITUTE(I4,",","#",LEN(I4)-LEN(SUBSTITUTE(I4,",","")))))," - ")) -> 18 | N4: =24*(C4-B4) -> 0.91666667 | O4: =G4/N4 -> 18.327273 | P4: =O4*(10/36) -> 5.0909091 | Q4: 20.35945
A5: 4 | B5: 0.2125 | C5: 0.25694444 | D5: 502 | E5: =IF(COUNTIF($D$2:D5,D5)=1,"D0",'Bus 53 and 46'!C10) -> D0 | F5: =IF(COUNTIF(D5:$D$233,D5)=1, "D0", IF('Bus 53 and 46'!C10 = "D2", "D1","D2")) -> D1 | G5: 32 | H5: =0.01005*(P5)^2-0.3113*P5+3.484 -> 1.58775 | I5: {=_xlfn.TEXTJOIN(", ", TRUE, _xlfn._xlws.FILTER('Events only'!$C$2:$C$411, ((Trips!B5 <= 'Events only'!$A$2:$A$411) * (Trips!C5 > 'Events only'!$A$2:$A$411)) + ((Trips!B5 > Trips!C5) * ((Trips!B5 <= 'Events only'!$A$2:$A$411) + ('Events only'!$A$2:$A$411 < Trips!C5))), "No Match"))} -> 3, 4, 5, 6, 7, 8, 9, 10, 11, 12, 13, 14, 15, 16, 17 | J5: =IF(E5="D0",LEFT(I5,FIND(",",I5)-1),IF(F5="D0",RIGHT(I5,LEN(I5)-FIND("#",SUBSTITUTE(I5,",","#",LEN(I5)-LEN(SUBSTITUTE(I5,",",""))))),"- ")) -> 3 | K5: =IF(F5="D0",RIGHT(I5,LEN(I5)-FIND("#",SUBSTITUTE(I5,",","#",LEN(I5)-LEN(SUBSTITUTE(I5,",",""))))),"- ") -> - | L5: =IF(E5="D1",LEFT(I5,FIND(",",I5)-1),IF(F5="D1",RIGHT(I5,LEN(I5)-FIND("#",SUBSTITUTE(I5,",","#",LEN(I5)-LEN(SUBSTITUTE(I5,",","")))))," - ")) -> 17 | M5: =IF(E5="D2",LEFT(I5,FIND(",",I5)-1),IF(F5="D2",RIGHT(I5,LEN(I5)-FIND("#",SUBSTITUTE(I5,",","#",LEN(I5)-LEN(SUBSTITUTE(I5,",","")))))," - ")) -> - | N5: =24*(C5-B5) -> 1.0666667 | O5: =G5/N5 -> 30 | P5: =O5*(10/36) -> 8.3333333 | Q5: 44.381156
A6: 5 | B6: 0.22777778 | C6: 0.26597222 | D6: 507 | E6: =IF(COUNTIF($D$2:D6,D6)=1,"D0",'Bus 53 and 46'!C11) -> D0 | F6: =IF(COUNTIF(D6:$D$233,D6)=1, "D0", IF('Bus 53 and 46'!C11 = "D2", "D1","D2")) -> D2 | G6: 16.8 | H6: =0.01005*(P6)^2-0.3113*P6+3.484 -> 2.1596694 | I6: {=_xlfn.TEXTJOIN(", ", TRUE, _xlfn._xlws.FILTER('Events only'!$C$2:$C$411, ((Trips!B6 <= 'Events only'!$A$2:$A$411) * (Trips!C6 > 'Events only'!$A$2:$A$411)) + ((Trips!B6 > Trips!C6) * ((Trips!B6 <= 'Events only'!$A$2:$A$411) + ('Events only'!$A$2:$A$411 < Trips!C6))), "No Match"))} -> 7, 8, 9, 10, 11, 12, 13, 14, 15, 16, 17, 18, 19, 20, 21 | J6: =IF(E6="D0",LEFT(I6,FIND(",",I6)-1),IF(F6="D0",RIGHT(I6,LEN(I6)-FIND("#",SUBSTITUTE(I6,",","#",LEN(I6)-LEN(SUBSTITUTE(I6,",",""))))),"- ")) -> 7 | K6: =IF(F6="D0",RIGHT(I6,LEN(I6)-FIND("#",SUBSTITUTE(I6,",","#",LEN(I6)-LEN(SUBSTITUTE(I6,",",""))))),"- ") -> - | L6: =IF(E6="D1",LEFT(I6,FIND(",",I6)-1),IF(F6="D1",RIGHT(I6,LEN(I6)-FIND("#",SUBSTITUTE(I6,",","#",LEN(I6)-LEN(SUBSTITUTE(I6,",","")))))," - ")) -> - | M6: =IF(E6="D2",LEFT(I6,FIND(",",I6)-1),IF(F6="D2",RIGHT(I6,LEN(I6)-FIND("#",SUBSTITUTE(I6,",","#",LEN(I6)-LEN(SUBSTITUTE(I6,",","")))))," - ")) -> 21 | N6: =24*(C6-B6) -> 0.91666667 | O6: =G6/N6 -> 18.327273 | P6: =O6*(10/36) -> 5.0909091 | Q6: 20.35945
A7: 6 | B7: 0.23402778 | C7: 0.27222222 | D7: 508 | E7: =IF(COUNTIF($D$2:D7,D7)=1,"D0",'Bus 53 and 46'!C12) -> D0 | F7: =IF(COUNTIF(D7:$D$233,D7)=1, "D0", IF('Bus 53 and 46'!C12 = "D2", "D1","D2")) -> D2 | G7: 16.8 | H7: =0.01005*(P7)^2-0.3113*P7+3.484 -> 2.1596694 | I7: {=_xlfn.TEXTJOIN(", ", TRUE, _xlfn._xlws.FILTER('Events only'!$C$2:$C$411, ((Trips!B7 <= 'Events only'!$A$2:$A$411) * (Trips!C7 > 'Events only'!$A$2:$A$411)) + ((Trips!B7 > Trips!C7) * ((Trips!B7 <= 'Events only'!$A$2:$A$411) + ('Events only'!$A$2:$A$411 < Trips!C7))), "No Match"))} -> 8, 9, 10, 11, 12, 13, 14, 15, 16, 17, 18, 19, 20, 21, 22, 23, 24, 25, 26 | J7: =IF(E7="D0",LEFT(I7,FIND(",",I7)-1),IF(F7="D0",RIGHT(I7,LEN(I7)-FIND("#",SUBSTITUTE(I7,",","#",LEN(I7)-LEN(SUBSTITUTE(I7,",",""))))),"- ")) -> 8 | K7: =IF(F7="D0",RIGHT(I7,LEN(I7)-FIND("#",SUBSTITUTE(I7,",","#",LEN(I7)-LEN(SUBSTITUTE(I7,",",""))))),"- ") -> - | L7: =IF(E7="D1",LEFT(I7,FIND(",",I7)-1),IF(F7="D1",RIGHT(I7,LEN(I7)-FIND("#",SUBSTITUTE(I7,",","#",LEN(I7)-LEN(SUBSTITUTE(I7,",","")))))," - ")) -> - | M7: =IF(E7="D2",LEFT(I7,FIND(",",I7)-1),IF(F7="D2",RIGHT(I7,LEN(I7)-FIND("#",SUBSTITUTE(I7,",","#",LEN(I7)-LEN(SUBSTITUTE(I7,",","")))))," - ")) -> 26 | N7: =24*(C7-B7) -> 0.91666667 | O7: =G7/N7 -> 18.327273 | P7: =O7*(10/36) -> 5.0909091 | Q7: 20.35945
A8: 7 | B8: 0.225 | C8: 0.26944444 | D8: 503 | E8: =IF(COUNTIF($D$2:D8,D8)=1,"D0",'Bus 53 and 46'!C13) -> D0 | F8: =IF(COUNTIF(D8:$D$233,D8)=1, "D0", IF('Bus 53 and 46'!C13 = "D2", "D1","D2")) -> D1 | G8: 32 | H8: =0.01005*(P8)^2-0.3113*P8+3.484 -> 1.58775 | I8: {=_xlfn.TEXTJOIN(", ", TRUE, _xlfn._xlws.FILTER('Events only'!$C$2:$C$411, ((Trips!B8 <= 'Events only'!$A$2:$A$411) * (Trips!C8 > 'Events only'!$A$2:$A$411)) + ((Trips!B8 > Trips!C8) * ((Trips!B8 <= 'Events only'!$A$2:$A$411) + ('Events only'!$A$2:$A$411 < Trips!C8))), "No Match"))} -> 6, 7, 8, 9, 10, 11, 12, 13, 14, 15, 16, 17, 18, 19, 20, 21, 22, 23, 24 | J8: =IF(E8="D0",LEFT(I8,FIND(",",I8)-1),IF(F8="D0",RIGHT(I8,LEN(I8)-FIND("#",SUBSTITUTE(I8,",","#",LEN(I8)-LEN(SUBSTITUTE(I8,",",""))))),"- ")) -> 6 | K8: =IF(F8="D0",RIGHT(I8,LEN(I8)-FIND("#",SUBSTITUTE(I8,",","#",LEN(I8)-LEN(SUBSTITUTE(I8,",",""))))),"- ") -> - | L8: =IF(E8="D1",LEFT(I8,FIND(",",I8)-1),IF(F8="D1",RIGHT(I8,LEN(I8)-FIND("#",SUBSTITUTE(I8,",","#",LEN(I8)-LEN(SUBSTITUTE(I8,",","")))))," - ")) -> 24 | M8: =IF(E8="D2",LEFT(I8,FIND(",",I8)-1),IF(F8="D2",RIGHT(I8,LEN(I8)-FIND("#",SUBSTITUTE(I8,",","#",LEN(I8)-LEN(SUBSTITUTE(I8,",","")))))," - ")) -> - | N8: =24*(C8-B8) -> 1.0666667 | O8: =G8/N8 -> 30 | P8: =O8*(10/36) -> 8.3333333 | Q8: 44.381156
A9: 8 | B9: 0.23819444 | C9: 0.27638889 | D9: 509 | E9: =IF(COUNTIF($D$2:D9,D9)=1,"D0",'Bus 53 and 46'!C14) -> D0 | F9: =IF(COUNTIF(D9:$D$233,D9)=1, "D0", IF('Bus 53 and 46'!C14 = "D2", "D1","D2")) -> D2 | G9: 16.8 | H9: =0.01005*(P9)^2-0.3113*P9+3.484 -> 2.1596694 | I9: {=_xlfn.TEXTJOIN(", ", TRUE, _xlfn._xlws.FILTER('Events only'!$C$2:$C$411, ((Trips!B9 <= 'Events only'!$A$2:$A$411) * (Trips!C9 > 'Events only'!$A$2:$A$411)) + ((Trips!B9 > Trips!C9) * ((Trips!B9 <= 'Events only'!$A$2:$A$411) + ('Events only'!$A$2:$A$411 < Trips!C9))), "No Match"))} -> 10, 11, 12, 13, 14, 15, 16, 17, 18, 19, 20, 21, 22, 23, 24, 25, 26, 27, 28 | J9: =IF(E9="D0",LEFT(I9,FIND(",",I9)-1),IF(F9="D0",RIGHT(I9,LEN(I9)-FIND("#",SUBSTITUTE(I9,",","#",LEN(I9)-LEN(SUBSTITUTE(I9,",",""))))),"- ")) -> 10 | K9: =IF(F9="D0",RIGHT(I9,LEN(I9)-FIND("#",SUBSTITUTE(I9,",","#",LEN(I9)-LEN(SUBSTITUTE(I9,",",""))))),"- ") -> - | L9: =IF(E9="D1",LEFT(I9,FIND(",",I9)-1),IF(F9="D1",RIGHT(I9,LEN(I9)-FIND("#",SUBSTITUTE(I9,",","#",LEN(I9)-LEN(SUBSTITUTE(I9,",","")))))," - ")) -> - | M9: =IF(E9="D2",LEFT(I9,FIND(",",I9)-1),IF(F9="D2",RIGHT(I9,LEN(I9)-FIND("#",SUBSTITUTE(I9,",","#",LEN(I9)-LEN(SUBSTITUTE(I9,",","")))))," - ")) -> 28 | N9: =24*(C9-B9) -> 0.91666667 | O9: =G9/N9 -> 18.327273 | P9: =O9*(10/36) -> 5.0909091 | Q9: 20.35945
A10: 9 | B10: 0.24236111 | C10: 0.28125 | D10: 510 | E10: =IF(COUNTIF($D$2:D10,D10)=1,"D0",'Bus 53 and 46'!C15) -> D0 | F10: =IF(COUNTIF(D10:$D$233,D10)=1, "D0", IF('Bus 53 and 46'!C15 = "D2", "D1","D2")) -> D2 | G10: 16.8 | H10: =0.01005*(P10)^2-0.3113*P10+3.484 -> 2.17875 | I10: {=_xlfn.TEXTJOIN(", ", TRUE, _xlfn._xlws.FILTER('Events only'!$C$2:$C$411, ((Trips!B10 <= 'Events only'!$A$2:$A$411) * (Trips!C10 > 'Events only'!$A$2:$A$411)) + ((Trips!B10 > Trips!C10) * ((Trips!B10 <= 'Events only'!$A$2:$A$411) + ('Events only'!$A$2:$A$411 < Trips!C10))), "No Match"))} -> 11, 12, 13, 14, 15, 16, 17, 18, 19, 20, 21, 22, 23, 24, 25, 26, 27, 28, 29, 30, 31 | J10: =IF(E10="D0",LEFT(I10,FIND(",",I10)-1),IF(F10="D0",RIGHT(I10,LEN(I10)-FIND("#",SUBSTITUTE(I10,",","#",LEN(I10)-LEN(SUBSTITUTE(I10,",",""))))),"- ")) -> 11 | K10: =IF(F10="D0",RIGHT(I10,LEN(I10)-FIND("#",SUBSTITUTE(I10,",","#",LEN(I10)-LEN(SUBSTITUTE(I10,",",""))))),"- ") -> - | L10: =IF(E10="D1",LEFT(I10,FIND(",",I10)-1),IF(F10="D1",RIGHT(I10,LEN(I10)-FIND("#",SUBSTITUTE(I10,",","#",LEN(I10)-LEN(SUBSTITUTE(I10,",","")))))," - ")) -> - | M10: =IF(E10="D2",LEFT(I10,FIND(",",I10)-1),IF(F10="D2",RIGHT(I10,LEN(I10)-FIND("#",SUBSTITUTE(I10,",","#",LEN(I10)-LEN(SUBSTITUTE(I10,",","")))))," - ")) -> 31 | N10: =24*(C10-B10) -> 0.93333333 | O10: =G10/N10 -> 18 | P10: =O10*(10/36) -> 5 | Q10: 19.865616
A11: 10 | B11: 0.23541667 | C11: 0.28055556 | D11: 505 | E11: =IF(COUNTIF($D$2:D11,D11)=1,"D0",'Bus 53 and 46'!C16) -> D0 | F11: =IF(COUNTIF(D11:$D$233,D11)=1, "D0", IF('Bus 53 and 46'!C16 = "D2", "D1","D2")) -> D1 | G11: 32 | H11: =0.01005*(P11)^2-0.3113*P11+3.484 -> 1.6063511 | I11: {=_xlfn.TEXTJOIN(", ", TRUE, _xlfn._xlws.FILTER('Events only'!$C$2:$C$411, ((Trips!B11 <= 'Events only'!$A$2:$A$411) * (Trips!C11 > 'Events only'!$A$2:$A$411)) + ((Trips!B11 > Trips!C11) * ((Trips!B11 <= 'Events only'!$A$2:$A$411) + ('Events only'!$A$2:$A$411 < Trips!C11))), "No Match"))} -> 9, 10, 11, 12, 13, 14, 15, 16, 17, 18, 19, 20, 21, 22, 23, 24, 25, 26, 27, 28, 29, 30 | J11: =IF(E11="D0",LEFT(I11,FIND(",",I11)-1),IF(F11="D0",RIGHT(I11,LEN(I11)-FIND("#",SUBSTITUTE(I11,",","#",LEN(I11)-LEN(SUBSTITUTE(I11,",",""))))),"- ")) -> 9 | K11: =IF(F11="D0",RIGHT(I11,LEN(I11)-FIND("#",SUBSTITUTE(I11,",","#",LEN(I11)-LEN(SUBSTITUTE(I11,",",""))))),"- ") -> - | L11: =IF(E11="D1",LEFT(I11,FIND(",",I11)-1),IF(F11="D1",RIGHT(I11,LEN(I11)-FIND("#",SUBSTITUTE(I11,",","#",LEN(I11)-LEN(SUBSTITUTE(I11,",","")))))," - ")) -> 30 | M11: =IF(E11="D2",LEFT(I11,FIND(",",I11)-1),IF(F11="D2",RIGHT(I11,LEN(I11)-FIND("#",SUBSTITUTE(I11,",","#",LEN(I11)-LEN(SUBSTITUTE(I11,",","")))))," - ")) -> - | N11: =24*(C11-B11) -> 1.0833333 | O11: =G11/N11 -> 29.538462 | P11: =O11*(10/36) -> 8.2051282 | Q11: 42.659527
A12: 11 | B12: 0.25347222 | C12: 0.28541667 | D12: 501 | E12: =IF(COUNTIF($D$2:D12,D12)=1,"D0",'Bus 53 and 46'!C17) -> D1 | F12: =IF(COUNTIF(D12:$D$233,D12)=1, "D0", IF('Bus 53 and 46'!C17 = "D2", "D1","D2")) -> D2 | G12: 14.4 | H12: =0.01005*(P12)^2-0.3113*P12+3.484 -> 2.1333989 | I12: {=_xlfn.TEXTJOIN(", ", TRUE, _xlfn._xlws.FILTER('Events only'!$C$2:$C$411, ((Trips!B12 <= 'Events only'!$A$2:$A$411) * (Trips!C12 > 'Events only'!$A$2:$A$411)) + ((Trips!B12 > Trips!C12) * ((Trips!B12 <= 'Events only'!$A$2:$A$411) + ('Events only'!$A$2:$A$411 < Trips!C12))), "No Match"))} -> 16, 17, 18, 19, 20, 21, 22, 23, 24, 25, 26, 27, 28, 29, 30, 31, 32, 33 | J12: =IF(E12="D0",LEFT(I12,FIND(",",I12)-1),IF(F12="D0",RIGHT(I12,LEN(I12)-FIND("#",SUBSTITUTE(I12,",","#",LEN(I12)-LEN(SUBSTITUTE(I12,",",""))))),"- ")) -> - | K12: =IF(F12="D0",RIGHT(I12,LEN(I12)-FIND("#",SUBSTITUTE(I12,",","#",LEN(I12)-LEN(SUBSTITUTE(I12,",",""))))),"- ") -> - | L12: =IF(E12="D1",LEFT(I12,FIND(",",I12)-1),IF(F12="D1",RIGHT(I12,LEN(I12)-FIND("#",SUBSTITUTE(I12,",","#",LEN(I12)-LEN(SUBSTITUTE(I12,",","")))))," - ")) -> 16 | M12: =IF(E12="D2",LEFT(I12,FIND(",",I12)-1),IF(F12="D2",RIGHT(I12,LEN(I12)-FIND("#",SUBSTITUTE(I12,",","#",LEN(I12)-LEN(SUBSTITUTE(I12,",","")))))," - ")) -> 33 | N12: =24*(C12-B12) -> 0.76666667 | O12: =G12/N12 -> 18.782609 | P12: =O12*(10/36) -> 5.2173913 | Q12: 17.027671
A13: 12 | B13: 0.25069444 | C13: 0.29097222 | D13: 511 | E13: =IF(COUNTIF($D$2:D13,D13)=1,"D0",'Bus 53 and 46'!C18) -> D0 | F13: =IF(COUNTIF(D13:$D$233,D13)=1, "D0", IF('Bus 53 and 46'!C18 = "D2", "D1","D2")) -> D2 | G13: 16.8 | H13: =0.01005*(P13)^2-0.3113*P13+3.484 -> 2.2153936 | I13: {=_xlfn.TEXTJOIN(", ", TRUE, _xlfn._xlws.FILTER('Events only'!$C$2:$C$411, ((Trips!B13 <= 'Events only'!$A$2:$A$411) * (Trips!C13 > 'Events only'!$A$2:$A$411)) + ((Trips!B13 > Trips!C13) * ((Trips!B13 <= 'Events only'!$A$2:$A$411) + ('Events only'!$A$2:$A$411 < Trips!C13))), "No Match"))} -> 14, 15, 16, 17, 18, 19, 20, 21, 22, 23, 24, 25, 26, 27, 28, 29, 30, 31, 32, 33, 34, 35, 36 | J13: =IF(E13="D0",LEFT(I13,FIND(",",I13)-1),IF(F13="D0",RIGHT(I13,LEN(I13)-FIND("#",SUBSTITUTE(I13,",","#",LEN(I13)-LEN(SUBSTITUTE(I13,",",""))))),"- ")) -> 14 | K13: =IF(F13="D0",RIGHT(I13,LEN(I13)-FIND("#",SUBSTITUTE(I13,",","#",LEN(I13)-LEN(SUBSTITUTE(I13,",",""))))),"- ") -> - | L13: =IF(E13="D1",LEFT(I13,FIND(",",I13)-1),IF(F13="D1",RIGHT(I13,LEN(I13)-FIND("#",SUBSTITUTE(I13,",","#",LEN(I13)-LEN(SUBSTITUTE(I13,",","")))))," - ")) -> - | M13: =IF(E13="D2",LEFT(I13,FIND(",",I13)-1),IF(F13="D2",RIGHT(I13,LEN(I13)-FIND("#",SUBSTITUTE(I13,",","#",LEN(I13)-LEN(SUBSTITUTE(I13,",","")))))," - ")) -> 36 | N13: =24*(C13-B13) -> 0.96666667 | O13: =G13/N13 -> 17.37931 | P13: =O13*(10/36) -> 4.8275862 | Q13: 19.09824
... A226: 225 | B226: 0.96736111 | C226: 0.99583333 | D226: 525 | E226: =IF(COUNTIF($D$2:D226,D226)=1,"D0",'Bus 53 and 46'!C231) -> D2 | F226: =IF(COUNTIF(D226:$D$233,D226)=1, "D0", IF('Bus 53 and 46'!C231 = "D2", "D1","D2")) -> D1 | G226: 14.4 | H226: =0.01005*(P226)^2-0.3113*P226+3.484 -> 2.0061225 | I226: {=_xlfn.TEXTJOIN(", ", TRUE, _xlfn._xlws.FILTER('Events only'!$C$2:$C$411, ((Trips!B226 <= 'Events only'!$A$2:$A$411) * (Trips!C226 > 'Events only'!$A$2:$A$411)) + ((Trips!B226 > Trips!C226) * ((Trips!B226 <= 'Events only'!$A$2:$A$411) + ('Events only'!$A$2:$A$411 < Trips!C226))), "No Match"))} -> 387, 388, 389, 390, 391, 392, 393, 394 | J226: =IF(E226="D0",LEFT(I226,FIND(",",I226)-1),IF(F226="D0",RIGHT(I226,LEN(I226)-FIND("#",SUBSTITUTE(I226,",","#",LEN(I226)-LEN(SUBSTITUTE(I226,",",""))))),"- ")) -> - | K226: =IF(F226="D0",RIGHT(I226,LEN(I226)-FIND("#",SUBSTITUTE(I226,",","#",LEN(I226)-LEN(SUBSTITUTE(I226,",",""))))),"- ") -> - | L226: =IF(E226="D1",LEFT(I226,FIND(",",I226)-1),IF(F226="D1",RIGHT(I226,LEN(I226)-FIND("#",SUBSTITUTE(I226,",","#",LEN(I226)-LEN(SUBSTITUTE(I226,",","")))))," - ")) -> 394 | M226: =IF(E226="D2",LEFT(I226,FIND(",",I226)-1),IF(F226="D2",RIGHT(I226,LEN(I226)-FIND("#",SUBSTITUTE(I226,",","#",LEN(I226)-LEN(SUBSTITUTE(I226,",","")))))," - ")) -> 387 | N226: =24*(C226-B226) -> 0.68333333 | O226: =G226/N226 -> 21.073171 | P226: =O226*(10/36) -> 5.8536585 | Q226: 19.97152
A227: 226 | B227: 0.97708333 | C227: 0.024305556 | D227: 521 | E227: =IF(COUNTIF($D$2:D227,D227)=1,"D0",'Bus 53 and 46'!C232) -> D1 | F227: =IF(COUNTIF(D227:$D$233,D227)=1, "D0", IF('Bus 53 and 46'!C232 = "D2", "D1","D2")) -> D0 | G227: 32 | H227: =0.01005*(P227)^2-0.3113*P227+3.484 -> 1.6606551 | I227: {=_xlfn.TEXTJOIN(", ", TRUE, _xlfn._xlws.FILTER('Events only'!$C$2:$C$411, ((Trips!B227 <= 'Events only'!$A$2:$A$411) * (Trips!C227 > 'Events only'!$A$2:$A$411)) + ((Trips!B227 > Trips!C227) * ((Trips!B227 <= 'Events only'!$A$2:$A$411) + ('Events only'!$A$2:$A$411 < Trips!C227))), "No Match"))} -> 389, 390, 391, 392, 393, 394, 395, 396, 397, 398, 399, 400, 401 | J227: =IF(E227="D0",LEFT(I227,FIND(",",I227)-1),IF(F227="D0",RIGHT(I227,LEN(I227)-FIND("#",SUBSTITUTE(I227,",","#",LEN(I227)-LEN(SUBSTITUTE(I227,",",""))))),"- ")) -> 401 | K227: =IF(F227="D0",RIGHT(I227,LEN(I227)-FIND("#",SUBSTITUTE(I227,",","#",LEN(I227)-LEN(SUBSTITUTE(I227,",",""))))),"- ") -> 401 | L227: =IF(E227="D1",LEFT(I227,FIND(",",I227)-1),IF(F227="D1",RIGHT(I227,LEN(I227)-FIND("#",SUBSTITUTE(I227,",","#",LEN(I227)-LEN(SUBSTITUTE(I227,",","")))))," - ")) -> 389 | M227: =IF(E227="D2",LEFT(I227,FIND(",",I227)-1),IF(F227="D2",RIGHT(I227,LEN(I227)-FIND("#",SUBSTITUTE(I227,",","#",LEN(I227)-LEN(SUBSTITUTE(I227,",","")))))," - ")) -> - | N227: =24*MOD((C227-B227),1) -> 1.1333333 | O227: =G227/N227 -> 28.235294 | P227: =O227*(10/36) -> 7.8431373 | Q227: 38.779904
A228: 227 | B228: 0.97777778 | C228: 0.013194444 | D228: 510 | E228: =IF(COUNTIF($D$2:D228,D228)=1,"D0",'Bus 53 and 46'!C233) -> D2 | F228: =IF(COUNTIF(D228:$D$233,D228)=1, "D0", IF('Bus 53 and 46'!C233 = "D2", "D1","D2")) -> D0 | G228: 16.8 | H228: =0.01005*(P228)^2-0.3113*P228+3.484 -> 2.0778316 | I228: {=_xlfn.TEXTJOIN(", ", TRUE, _xlfn._xlws.FILTER('Events only'!$C$2:$C$411, ((Trips!B228 <= 'Events only'!$A$2:$A$411) * (Trips!C228 > 'Events only'!$A$2:$A$411)) + ((Trips!B228 > Trips!C228) * ((Trips!B228 <= 'Events only'!$A$2:$A$411) + ('Events only'!$A$2:$A$411 < Trips!C228))), "No Match"))} -> 390, 391, 392, 393, 394, 395, 396, 397, 398, 399 | J228: =IF(E228="D0",LEFT(I228,FIND(",",I228)-1),IF(F228="D0",RIGHT(I228,LEN(I228)-FIND("#",SUBSTITUTE(I228,",","#",LEN(I228)-LEN(SUBSTITUTE(I228,",",""))))),"- ")) -> 399 | K228: =IF(F228="D0",RIGHT(I228,LEN(I228)-FIND("#",SUBSTITUTE(I228,",","#",LEN(I228)-LEN(SUBSTITUTE(I228,",",""))))),"- ") -> 399 | L228: =IF(E228="D1",LEFT(I228,FIND(",",I228)-1),IF(F228="D1",RIGHT(I228,LEN(I228)-FIND("#",SUBSTITUTE(I228,",","#",LEN(I228)-LEN(SUBSTITUTE(I228,",","")))))," - ")) -> - | M228: =IF(E228="D2",LEFT(I228,FIND(",",I228)-1),IF(F228="D2",RIGHT(I228,LEN(I228)-FIND("#",SUBSTITUTE(I228,",","#",LEN(I228)-LEN(SUBSTITUTE(I228,",","")))))," - ")) -> 390 | N228: =24*MOD((C228-B228),1) -> 0.85 | O228: =G228/N228 -> 19.764706 | P228: =O228*(10/36) -> 5.4901961 | Q228: 23.300107
A229: 228 | B229: 0.9875 | C229: 0.034722222 | D229: 505 | E229: =IF(COUNTIF($D$2:D229,D229)=1,"D0",'Bus 53 and 46'!C234) -> D1 | F229: =IF(COUNTIF(D229:$D$233,D229)=1, "D0", IF('Bus 53 and 46'!C234 = "D2", "D1","D2")) -> D0 | G229: 32 | H229: =0.01005*(P229)^2-0.3113*P229+3.484 -> 1.6606551 | I229: {=_xlfn.TEXTJOIN(", ", TRUE, _xlfn._xlws.FILTER('Events only'!$C$2:$C$411, ((Trips!B229 <= 'Events only'!$A$2:$A$411) * (Trips!C229 > 'Events only'!$A$2:$A$411)) + ((Trips!B229 > Trips!C229) * ((Trips!B229 <= 'Events only'!$A$2:$A$411) + ('Events only'!$A$2:$A$411 < Trips!C229))), "No Match"))} -> 393, 394, 395, 396, 397, 398, 399, 400, 401, 402, 403 | J229: =IF(E229="D0",LEFT(I229,FIND(",",I229)-1),IF(F229="D0",RIGHT(I229,LEN(I229)-FIND("#",SUBSTITUTE(I229,",","#",LEN(I229)-LEN(SUBSTITUTE(I229,",",""))))),"- ")) -> 403 | K229: =IF(F229="D0",RIGHT(I229,LEN(I229)-FIND("#",SUBSTITUTE(I229,",","#",LEN(I229)-LEN(SUBSTITUTE(I229,",",""))))),"- ") -> 403 | L229: =IF(E229="D1",LEFT(I229,FIND(",",I229)-1),IF(F229="D1",RIGHT(I229,LEN(I229)-FIND("#",SUBSTITUTE(I229,",","#",LEN(I229)-LEN(SUBSTITUTE(I229,",","")))))," - ")) -> 393 | M229: =IF(E229="D2",LEFT(I229,FIND(",",I229)-1),IF(F229="D2",RIGHT(I229,LEN(I229)-FIND("#",SUBSTITUTE(I229,",","#",LEN(I229)-LEN(SUBSTITUTE(I229,",","")))))," - ")) -> - | N229: =24*MOD((C229-B229),1) -> 1.1333333 | O229: =G229/N229 -> 28.235294 | P229: =O229*(10/36) -> 7.8431373 | Q229: 38.779904
A230: 229 | B230: 0.98819444 | C230: 0.023611111 | D230: 504 | E230: =IF(COUNTIF($D$2:D230,D230)=1,"D0",'Bus 53 and 46'!C235) -> D2 | F230: =IF(COUNTIF(D230:$D$233,D230)=1, "D0", IF('Bus 53 and 46'!C235 = "D2", "D1","D2")) -> D0 | G230: 16.8 | H230: =0.01005*(P230)^2-0.3113*P230+3.484 -> 2.0778316 | I230: {=_xlfn.TEXTJOIN(", ", TRUE, _xlfn._xlws.FILTER('Events only'!$C$2:$C$411, ((Trips!B230 <= 'Events only'!$A$2:$A$411) * (Trips!C230 > 'Events only'!$A$2:$A$411)) + ((Trips!B230 > Trips!C230) * ((Trips!B230 <= 'Events only'!$A$2:$A$411) + ('Events only'!$A$2:$A$411 < Trips!C230))), "No Match"))} -> 394, 395, 396, 397, 398, 399, 400 | J230: =IF(E230="D0",LEFT(I230,FIND(",",I230)-1),IF(F230="D0",RIGHT(I230,LEN(I230)-FIND("#",SUBSTITUTE(I230,",","#",LEN(I230)-LEN(SUBSTITUTE(I230,",",""))))),"- ")) -> 400 | K230: =IF(F230="D0",RIGHT(I230,LEN(I230)-FIND("#",SUBSTITUTE(I230,",","#",LEN(I230)-LEN(SUBSTITUTE(I230,",",""))))),"- ") -> 400 | L230: =IF(E230="D1",LEFT(I230,FIND(",",I230)-1),IF(F230="D1",RIGHT(I230,LEN(I230)-FIND("#",SUBSTITUTE(I230,",","#",LEN(I230)-LEN(SUBSTITUTE(I230,",","")))))," - ")) -> - | M230: =IF(E230="D2",LEFT(I230,FIND(",",I230)-1),IF(F230="D2",RIGHT(I230,LEN(I230)-FIND("#",SUBSTITUTE(I230,",","#",LEN(I230)-LEN(SUBSTITUTE(I230,",","")))))," - ")) -> 394 | N230: =24*MOD((C230-B230),1) -> 0.85 | O230: =G230/N230 -> 19.764706 | P230: =O230*(10/36) -> 5.4901961 | Q230: 23.300107
A231: 230 | B231: 0.99791667 | C231: 0.045138889 | D231: 525 | E231: =IF(COUNTIF($D$2:D231,D231)=1,"D0",'Bus 53 and 46'!C236) -> D1 | F231: =IF(COUNTIF(D231:$D$233,D231)=1, "D0", IF('Bus 53 and 46'!C236 = "D2", "D1","D2")) -> D0 | G231: 32 | H231: =0.01005*(P231)^2-0.3113*P231+3.484 -> 1.6606551 | I231: {=_xlfn.TEXTJOIN(", ", TRUE, _xlfn._xlws.FILTER('Events only'!$C$2:$C$411, ((Trips!B231 <= 'Events only'!$A$2:$A$411) * (Trips!C231 > 'Events only'!$A$2:$A$411)) + ((Trips!B231 > Trips!C231) * ((Trips!B231 <= 'Events only'!$A$2:$A$411) + ('Events only'!$A$2:$A$411 < Trips!C231))), "No Match"))} -> 396, 397, 398, 399, 400, 401, 402, 403, 404, 405 | J231: =IF(E231="D0",LEFT(I231,FIND(",",I231)-1),IF(F231="D0",RIGHT(I231,LEN(I231)-FIND("#",SUBSTITUTE(I231,",","#",LEN(I231)-LEN(SUBSTITUTE(I231,",",""))))),"- ")) -> 405 | K231: =IF(F231="D0",RIGHT(I231,LEN(I231)-FIND("#",SUBSTITUTE(I231,",","#",LEN(I231)-LEN(SUBSTITUTE(I231,",",""))))),"- ") -> 405 | L231: =IF(E231="D1",LEFT(I231,FIND(",",I231)-1),IF(F231="D1",RIGHT(I231,LEN(I231)-FIND("#",SUBSTITUTE(I231,",","#",LEN(I231)-LEN(SUBSTITUTE(I231,",","")))))," - ")) -> 396 | M231: =IF(E231="D2",LEFT(I231,FIND(",",I231)-1),IF(F231="D2",RIGHT(I231,LEN(I231)-FIND("#",SUBSTITUTE(I231,",","#",LEN(I231)-LEN(SUBSTITUTE(I231,",","")))))," - ")) -> - | N231: =24*MOD((C231-B231),1) -> 1.1333333 | O231: =G231/N231 -> 28.235294 | P231: =O231*(10/36) -> 7.8431373 | Q231: 38.779904
A232: 231 | B232: 0.99861111 | C232: 0.034027778 | D232: 528 | E232: =IF(COUNTIF($D$2:D232,D232)=1,"D0",'Bus 53 and 46'!C237) -> D2 | F232: =IF(COUNTIF(D232:$D$233,D232)=1, "D0", IF('Bus 53 and 46'!C237 = "D2", "D1","D2")) -> D0 | G232: 16.8 | H232: =0.01005*(P232)^2-0.3113*P232+3.484 -> 2.0778316 | I232: {=_xlfn.TEXTJOIN(", ", TRUE, _xlfn._xlws.FILTER('Events only'!$C$2:$C$411, ((Trips!B232 <= 'Events only'!$A$2:$A$411) * (Trips!C232 > 'Events only'!$A$2:$A$411)) + ((Trips!B232 > Trips!C232) * ((Trips!B232 <= 'Events only'!$A$2:$A$411) + ('Events only'!$A$2:$A$411 < Trips!C232))), "No Match"))} -> 397, 398, 399, 400, 401, 402 | J232: =IF(E232="D0",LEFT(I232,FIND(",",I232)-1),IF(F232="D0",RIGHT(I232,LEN(I232)-FIND("#",SUBSTITUTE(I232,",","#",LEN(I232)-LEN(SUBSTITUTE(I232,",",""))))),"- ")) -> 402 | K232: =IF(F232="D0",RIGHT(I232,LEN(I232)-FIND("#",SUBSTITUTE(I232,",","#",LEN(I232)-LEN(SUBSTITUTE(I232,",",""))))),"- ") -> 402 | L232: =IF(E232="D1",LEFT(I232,FIND(",",I232)-1),IF(F232="D1",RIGHT(I232,LEN(I232)-FIND("#",SUBSTITUTE(I232,",","#",LEN(I232)-LEN(SUBSTITUTE(I232,",","")))))," - ")) -> - | M232: =IF(E232="D2",LEFT(I232,FIND(",",I232)-1),IF(F232="D2",RIGHT(I232,LEN(I232)-FIND("#",SUBSTITUTE(I232,",","#",LEN(I232)-LEN(SUBSTITUTE(I232,",","")))))," - ")) -> 397 | N232: =24*MOD((C232-B232),1) -> 0.85 | O232: =G232/N232 -> 19.764706 | P232: =O232*(10/36) -> 5.4901961 | Q232: 23.300107
